Workbook

Sheet 集計
A1: cpp_shuffle | C1: 調査件数 | D1: csharp_shuffle | F1: 調査件数 | G1: java_shuffle | I1: 調査件数 | J1: javascript_shuffle | L1: 調査件数 | M1: php_shuffle | O1: 調査件数 | P1: ruby_shuffle | R1: 調査件数
B2: =SUM(B3:B7) -> 0 | C2: =SUM(C3:C7) -> 0 | E2: =SUM(E3:E7) -> 58 | F2: =SUM(F3:F7) -> 50 | H2: =SUM(H3:H7) -> 56 | I2: =SUM(I3:I7) -> 50 | K2: =SUM(K3:K7) -> 0 | L2: =SUM(L3:L7) -> 0 | N2: =SUM(N3:N7) -> 0 | O2: =SUM(O3:O7) -> 0 | Q2: =SUM(Q3:Q7) -> 24 | R2: =SUM(R3:R7) -> 23
A3: {=code!$A$1:$A$5} -> 差し戻し | B3: =COUNTIF(INDIRECT(A$1 & "!G2:G1000"), A3) -> 0 | C3: =IFERROR(__xludf.DUMMYFUNCTION("IF(NOT(REGEXMATCH(A3, ""誤検出|調査不能"")), B3, 0)"),0.0) -> 0 | D3: {=code!$A$1:$A$5} -> 差し戻し | E3: =COUNTIF(INDIRECT(D$1 & "!G2:G1000"), D3) -> 10 | F3: =IFERROR(__xludf.DUMMYFUNCTION("IF(NOT(REGEXMATCH(D3, ""誤検出|調査不能"")), E3, 0)"),10.0) -> 10 | G3: {=code!$A$1:$A$5} -> 差し戻し | H3: =COUNTIF(INDIRECT(G$1 & "!G2:G1000"), G3) -> 14 | I3: =IFERROR(__xludf.DUMMYFUNCTION("IF(NOT(REGEXMATCH(G3, ""誤検出|調査不能"")), H3, 0)"),14.0) -> 14 | J3: {=code!$A$1:$A$5} -> 差し戻し | K3: =COUNTIF(INDIRECT(J$1 & "!G2:G1000"), J3) -> 0 | L3: =IFERROR(__xludf.DUMMYFUNCTION("IF(NOT(REGEXMATCH(J3, ""誤検出|調査不能"")), K3, 0)"),0.0) -> 0 | M3: {=code!$A$1:$A$5} -> 差し戻し | N3: =COUNTIF(INDIRECT(M$1 & "!G2:G1000"), M3) -> 0 | O3: =IFERROR(__xludf.DUMMYFUNCTION("IF(NOT(REGEXMATCH(M3, ""誤検出|調査不能"")), N3, 0)"),0.0) -> 0 | P3: {=code!$A$1:$A$5} -> 差し戻し | Q3: =COUNTIF(INDIRECT(P$1 & "!G2:G1000"), P3) -> 2 | R3: =IFERROR(__xludf.DUMMYFUNCTION("IF(NOT(REGEXMATCH(P3, ""誤検出|調査不能"")), Q3, 0)"),2.0) -> 2
A4: 機能変更 | B4: =COUNTIF(INDIRECT(A$1 & "!G2:G1000"), A4) -> 0 | C4: =IFERROR(__xludf.DUMMYFUNCTION("IF(NOT(REGEXMATCH(A4, ""誤検出|調査不能"")), B4, 0)"),0.0) -> 0 | D4: 機能変更 | E4: =COUNTIF(INDIRECT(D$1 & "!G2:G1000"), D4) -> 34 | F4: =IFERROR(__xludf.DUMMYFUNCTION("IF(NOT(REGEXMATCH(D4, ""誤検出|調査不能"")), E4, 0)"),34.0) -> 34 | G4: 機能変更 | H4: =COUNTIF(INDIRECT(G$1 & "!G2:G1000"), G4) -> 27 | I4: =IFERROR(__xludf.DUMMYFUNCTION("IF(NOT(REGEXMATCH(G4, ""誤検出|調査不能"")), H4, 0)"),27.0) -> 27 | J4: 機能変更 | K4: =COUNTIF(INDIRECT(J$1 & "!G2:G1000"), J4) -> 0 | L4: =IFERROR(__xludf.DUMMYFUNCTION("IF(NOT(REGEXMATCH(J4, ""誤検出|調査不能"")), K4, 0)"),0.0) -> 0 | M4: 機能変更 | N4: =COUNTIF(INDIRECT(M$1 & "!G2:G1000"), M4) -> 0 | O4: =IFERROR(__xludf.DUMMYFUNCTION("IF(NOT(REGEXMATCH(M4, ""誤検出|調査不能"")), N4, 0)"),0.0) -> 0 | P4: 機能変更 | Q4: =COUNTIF(INDIRECT(P$1 & "!G2:G1000"), P4) -> 20 | R4: =IFERROR(__xludf.DUMMYFUNCTION("IF(NOT(REGEXMATCH(P4, ""誤検出|調査不能"")), Q4, 0)"),20.0) -> 20
A5: 機能削除 | B5: =COUNTIF(INDIRECT(A$1 & "!G2:G1000"), A5) -> 0 | C5: =IFERROR(__xludf.DUMMYFUNCTION("IF(NOT(REGEXMATCH(A5, ""誤検出|調査不能"")), B5, 0)"),0.0) -> 0 | D5: 機能削除 | E5: =COUNTIF(INDIRECT(D$1 & "!G2:G1000"), D5) -> 6 | F5: =IFERROR(__xludf.DUMMYFUNCTION("IF(NOT(REGEXMATCH(D5, ""誤検出|調査不能"")), E5, 0)"),6.0) -> 6 | G5: 機能削除 | H5: =COUNTIF(INDIRECT(G$1 & "!G2:G1000"), G5) -> 9 | I5: =IFERROR(__xludf.DUMMYFUNCTION("IF(NOT(REGEXMATCH(G5, ""誤検出|調査不能"")), H5, 0)"),9.0) -> 9 | J5: 機能削除 | K5: =COUNTIF(INDIRECT(J$1 & "!G2:G1000"), J5) -> 0 | L5: =IFERROR(__xludf.DUMMYFUNCTION("IF(NOT(REGEXMATCH(J5, ""誤検出|調査不能"")), K5, 0)"),0.0) -> 0 | M5: 機能削除 | N5: =COUNTIF(INDIRECT(M$1 & "!G2:G1000"), M5) -> 0 | O5: =IFERROR(__xludf.DUMMYFUNCTION("IF(NOT(REGEXMATCH(M5, ""誤検出|調査不能"")), N5, 0)"),0.0) -> 0 | P5: 機能削除 | Q5: =COUNTIF(INDIRECT(P$1 & "!G2:G1000"), P5) -> 1 | R5: =IFERROR(__xludf.DUMMYFUNCTION("IF(NOT(REGEXMATCH(P5, ""誤検出|調査不能"")), Q5, 0)"),1.0) -> 1
A6: 誤検出 | B6: =COUNTIF(INDIRECT(A$1 & "!G2:G1000"), A6) -> 0 | C6: =IFERROR(__xludf.DUMMYFUNCTION("IF(NOT(REGEXMATCH(A6, ""誤検出|調査不能"")), B6, 0)"),0.0) -> 0 | D6: 誤検出 | E6: =COUNTIF(INDIRECT(D$1 & "!G2:G1000"), D6) -> 8 | F6: =IFERROR(__xludf.DUMMYFUNCTION("IF(NOT(REGEXMATCH(D6, ""誤検出|調査不能"")), E6, 0)"),0.0) -> 0 | G6: 誤検出 | H6: =COUNTIF(INDIRECT(G$1 & "!G2:G1000"), G6) -> 5 | I6: =IFERROR(__xludf.DUMMYFUNCTION("IF(NOT(REGEXMATCH(G6, ""誤検出|調査不能"")), H6, 0)"),0.0) -> 0 | J6: 誤検出 | K6: =COUNTIF(INDIRECT(J$1 & "!G2:G1000"), J6) -> 0 | L6: =IFERROR(__xludf.DUMMYFUNCTION("IF(NOT(REGEXMATCH(J6, ""誤検出|調査不能"")), K6, 0)"),0.0) -> 0 | M6: 誤検出 | N6: =COUNTIF(INDIRECT(M$1 & "!G2:G1000"), M6) -> 0 | O6: =IFERROR(__xludf.DUMMYFUNCTION("IF(NOT(REGEXMATCH(M6, ""誤検出|調査不能"")), N6, 0)"),0.0) -> 0 | P6: 誤検出 | Q6: =COUNTIF(INDIRECT(P$1 & "!G2:G1000"), P6) -> 1 | R6: =IFERROR(__xludf.DUMMYFUNCTION("IF(NOT(REGEXMATCH(P6, ""誤検出|調査不能"")), Q6, 0)"),0.0) -> 0
A7: 調査不能 | B7: =COUNTIF(INDIRECT(A$1 & "!G2:G1000"), A7) -> 0 | C7: =IFERROR(__xludf.DUMMYFUNCTION("IF(NOT(REGEXMATCH(A7, ""誤検出|調査不能"")), B7, 0)"),0.0) -> 0 | D7: 調査不能 | E7: =COUNTIF(INDIRECT(D$1 & "!G2:G1000"), D7) -> 0 | F7: =IFERROR(__xludf.DUMMYFUNCTION("IF(NOT(REGEXMATCH(D7, ""誤検出|調査不能"")), E7, 0)"),0.0) -> 0 | G7: 調査不能 | H7: =COUNTIF(INDIRECT(G$1 & "!G2:G1000"), G7) -> 1 | I7: =IFERROR(__xludf.DUMMYFUNCTION("IF(NOT(REGEXMATCH(G7, ""誤検出|調査不能"")), H7, 0)"),0.0) -> 0 | J7: 調査不能 | K7: =COUNTIF(INDIRECT(J$1 & "!G2:G1000"), J7) -> 0 | L7: =IFERROR(__xludf.DUMMYFUNCTION("IF(NOT(REGEXMATCH(J7, ""誤検出|調査不能"")), K7, 0)"),0.0) -> 0 | M7: 調査不能 | N7: =COUNTIF(INDIRECT(M$1 & "!G2:G1000"), M7) -> 0 | O7: =IFERROR(__xludf.DUMMYFUNCTION("IF(NOT(REGEXMATCH(M7, ""誤検出|調査不能"")), N7, 0)"),0.0) -> 0 | P7: 調査不能 | Q7: =COUNTIF(INDIRECT(P$1 & "!G2:G1000"), P7) -> 0 | R7: =IFERROR(__xludf.DUMMYFUNCTION("IF(NOT(REGEXMATCH(P7, ""誤検出|調査不能"")), Q7, 0)"),0.0) -> 0

Sheet cpp_shuffle
B1: name_with_owner | C1: insert url | D1: delete url | E1: replacement_msg | F1: delete_msg | G1: coding | H1: insert commit | I1: insert src file | J1: insert src start pos | K1: insert dst file | L1: insert dst start pos | M1: delete commit | N1: delete src file | O1: delete src start pos | P1: delete dst file | Q1: delete dst start pos | R1: insert src file content | S1: insert dst file content | T1: delete src file content
A2: 0 | B2: kingsamchen_Eureka | C2: https://github.com/kingsamchen/Eureka/commit/a61aa11e56be33dda5cbcbc1f461652515d94a4b | E2: himsw: basically work | F2: himsw: use pure win32 gui | H2: 16965166a1f6d03434296da844a73fc09b0e0770 | I2: hey-i-am-still-working/himsw/main.cpp | J2: (8, 12) | K2: hey-i-am-still-working/himsw/main.cpp | L2: (45, 34) | M2: a61aa11e56be33dda5cbcbc1f461652515d94a4b | N2: hey-i-am-still-working/himsw/main.cpp | O2: (90, 23) | P2: hey-i-am-still-working/himsw/main.cpp | R2: { while (true) { himsw::labor_monitor::instance().tick(); std::this_thread::sleep_for(std::chrono::seconds(60)); } return 0; } | S2: { this->caption("Hey I AM Still Working"); lbl_info_.size(this->size()); lbl_info_.caption("monitoring..."); timer_.elapse([] { himsw::labor_monitor::instance().tick(); }); timer_.interval(std::chrono::seconds(30)); timer_.start(); } | T2: [] { himsw::labor_monitor::instance().tick(); }
A3: 1 | B3: apple_swift | C3: https://github.com/apple/swift/commit/bb067f4d6827f9be36df8779552cfc6c595e1c00 | D3: https://github.com/apple/swift/commit/8b926af49a2aad883cb358812aa67137e8199222 | E3: Revert "EscapeAnalysis: add node flags and change the meaning of "escaping"" | F3: EscapeAnalysis: Add PointerKind and interior/reference flags Categorize three kinds of pointers: NoPointer (don't create a node) ReferenceOnly (safe to make normal assumptions) AnyPointer (may have addresses, rawpointers, or any mix of thoses with references) Flag ConnectionGraph nodes as - hasReferenceOnly - isInterior An interior node always has an additional content node. All sorts of arbitrary node merging is supported. Nodes with totally different properties can be safely merged. Interior nodes can safely be merged with their field content (which does happen surprisingly often). Alias analysis will use these flags to safely make assumptions about properties of the connection graph. | H3: bb067f4d6827f9be36df8779552cfc6c595e1c00 | I3: lib/SILOptimizer/Analysis/EscapeAnalysis.cpp | J3: (914, 3) | K3: lib/SILOptimizer/Analysis/EscapeAnalysis.cpp | L3: (1570, 3) | M3: 8b926af49a2aad883cb358812aa67137e8199222 | N3: lib/SILOptimizer/Analysis/EscapeAnalysis.cpp | O3: (1570, 16) | P3: lib/SILOptimizer/Analysis/EscapeAnalysis.cpp | R3: bool contentHasReferenceOnly = EA->hasReferenceOnly(addrVal->getType().getObjectType(), *F); | S3: auto hasRC = [&](){ return mustContainReference(baseAddr->getType(), *F) || mustContainReference(addrVal->getType(), *F); }; | T3: [&](){ return mustContainReference(baseAddr->getType(), *F) || mustContainReference(addrVal->getType(), *F); }
A4: 2 | B4: apple_swift | C4: https://github.com/apple/swift/commit/9dbd5829debeca41abe8035393ba9f493408c54d | D4: https://github.com/apple/swift/commit/927cf42ba656051cb51007293c19349b60ddd965 | E4: [CodeCompletion] Support type checking attributes even if they are not part of the AST The code completion might occur inside an attriubte that isn’t part of the AST because it’s missing a `VarDecl` that it could be attached to. In these cases, record the `CustomAttr` and type check it standalone, pretending it was part of a `DeclContext`. This also fixes a few issues where code completion previously wouldn’t find the attribute constructor call and thus wasn’t providing code completion inside the property wrapper. rdar://92842803 | F4: [CodeCompletion] Move implementation of solver-based completions to their own functions This has the benefit that in case of a code completion crash, we can see what kind of completion crashed without having to symbolicate the stack trace using LLDB. It also made `trySolverCompletion` small enough that we can inline it into `doneParsing`, which makes debugging easier because you won’t accidentally step over the call to `trySolverCompletion`, which actually performs the completion. | H4: 9dbd5829debeca41abe8035393ba9f493408c54d | I4: lib/IDE/CodeCompletion.cpp | J4: (1326, 75) | K4: lib/IDE/CodeCompletion.cpp | L4: (1337, 75) | M4: 927cf42ba656051cb51007293c19349b60ddd965 | N4: lib/IDE/CodeCompletion.cpp | O4: (1458, 30) | P4: lib/IDE/CodeCompletion.cpp | R4: { assert(ParsedExpr || CurDeclContext); SourceLoc CompletionLoc = ParsedExpr ? ParsedExpr->getLoc() : CurDeclContext->getASTContext().SourceMgr.getCodeCompletionLoc(); switch (Kind) { case CompletionKind::DotExpr: { assert(CodeCompleteTokenExpr); assert(CurDeclContext); DotExprTypeCheckCompletionCallback Lookup(CodeCompleteTokenExpr, CurDeclContext); llvm::SaveAndRestore<TypeCheckCompletionCallback*> CompletionCollector(Context.CompletionCallback, &Lookup); typeCheckContextAt(CurDeclContext, CompletionLoc); // This (hopefully) only happens in cases where the expression isn't // typechecked during normal compilation either (e.g. member completion in a // switch case where there control expression is invalid). Having normal // typechecking still resolve even these cases would be beneficial for // tooling in general though. if (!Lookup.gotCallback()) Lookup.fallbackTypeCheck(CurDeclContext); addKeywords(CompletionContext.getResultSink(), MaybeFuncBody); Expr *CheckedBase = CodeCompleteTokenExpr->getBase(); Lookup.deliverResults(CheckedBase, CurDeclContext, DotLoc, isInsideObjCSelector(), CompletionContext, Consumer); return true; } | S4: { assert(ParsedExpr || CurDeclContext); SourceLoc CompletionLoc = ParsedExpr ? ParsedExpr->getLoc() : CurDeclContext->getASTContext().SourceMgr.getCodeCompletionLoc(); auto typeCheckWithLookup = [this, &CompletionLoc]( TypeCheckCompletionCallback &Lookup) { llvm::SaveAndRestore<TypeCheckCompletionCallback*> CompletionCollector(Context.CompletionCallback, &Lookup); if (AttrWithCompletion) { /// The attribute might not be attached to the AST if there is no var decl /// it could be attached to. Type check it standalone. ASTNode Call = CallExpr::create( CurDeclContext->getASTContext(), AttrWithCompletion->getTypeExpr(), AttrWithCompletion->getArgs(), /*implicit=*/true); typeCheckContextAt( TypeCheckASTNodeAtLocContext::node(CurDeclContext, Call), CompletionLoc); } | T4: [this, &CompletionLoc]( TypeCheckCompletionCallback &Lookup) { llvm::SaveAndRestore<TypeCheckCompletionCallback*> CompletionCollector(Context.CompletionCallback, &Lookup); if (AttrWithCompletion) { /// The attribute might not be attached to the AST if there is no var /// decl it could be attached to. Type check it standalone. // First try to check it as an attached macro. auto resolvedMacro = evaluateOrDefault( CurDeclContext->getASTContext().evaluator, ResolveMacroRequest{AttrWithCompletion, CurDeclContext}, ConcreteDeclRef()); // If that fails, type check as a call to the attribute's type. This is // how, e.g., property wrappers are modelled. if (!resolvedMacro) { ASTNode Call = CallExpr::create( CurDeclContext->getASTContext(), AttrWithCompletion->getTypeExpr(), AttrWithCompletion->getArgs(), /*implicit=*/true); typeCheckContextAt( TypeCheckASTNodeAtLocContext::node(CurDeclContext, Call), CompletionLoc); } } else { typeCheckContextAt( TypeCheckASTNodeAtLocContext::declContext(CurDeclContext), CompletionLoc); } // This (hopefully) only happens in cases where the expression isn't // typechecked during normal compilation either (e.g. member completion in a // switch case where there control expression is invalid). Having normal // typechecking still resolve even these cases would be beneficial for // tooling in general though. if (!Lookup.gotCallback()) { if (Context.TypeCheckerOpts.DebugConstraintSolver) { llvm::errs() << "--- Fallback typecheck for code completion ---\n"; } Lookup.fallbackTypeCheck(CurDeclContext); } }
A5: 3 | B5: ElunaLuaEngine_ElunaTrinityWotlk | C5: https://github.com/ElunaLuaEngine/ElunaTrinityWotlk/commit/14c2b2d6cd2303609f1a1859e727ace7b8ea649c | D5: https://github.com/ElunaLuaEngine/ElunaTrinityWotlk/commit/3d3d0492ab8dad40d5590e80f45bdfbdbcbe7497 | E5: Core/Spell: added some helpers to SpellInfo to reduce code duplication | F5: Core/Spells: Check both main and offhand weapons if spell attributes require that (see Stormstrike) * This restores the check probably unintentionally dropped in 14c2b2d6cd2303609f1a1859e727ace7b8ea649c * Build fix | H5: 14c2b2d6cd2303609f1a1859e727ace7b8ea649c | I5: src/server/game/Spells/Spell.cpp | J5: (6589, 13) | K5: src/server/game/Spells/Spell.cpp | L5: (6554, 9) | M5: 3d3d0492ab8dad40d5590e80f45bdfbdbcbe7497 | N5: src/server/game/Spells/Spell.cpp | O5: (6554, 35) | P5: src/server/game/Spells/Spell.cpp | R5: Item* item = m_caster->ToPlayer()->GetWeaponForAttack(OFF_ATTACK); | S5: SpellCastResult itemRes = [this]() -> SpellCastResult { switch (m_attackType) { case BASE_ATTACK: // main hand weapon required if (!m_spellInfo->HasAttribute(SPELL_ATTR3_MAIN_HAND)) return SPELL_CAST_OK; case OFF_ATTACK: // offhand hand weapon required if (!m_spellInfo->HasAttribute(SPELL_ATTR3_REQ_OFFHAND)) return SPELL_CAST_OK; default: return SPELL_CAST_OK; } Item const* item = m_caster->ToPlayer()->GetWeaponForAttack(m_attackType); | T5: [this]() -> SpellCastResult { switch (m_attackType) { case BASE_ATTACK: // main hand weapon required if (!m_spellInfo->HasAttribute(SPELL_ATTR3_MAIN_HAND)) return SPELL_CAST_OK; break; case OFF_ATTACK: // offhand hand weapon required if (!m_spellInfo->HasAttribute(SPELL_ATTR3_REQ_OFFHAND)) return SPELL_CAST_OK; break; default: return SPELL_CAST_OK; } Item const* item = m_caster->ToPlayer()->GetWeaponForAttack(m_attackType)
A6: 4 | B6: apple_swift | C6: https://github.com/apple/swift/commit/0beddca9e93643a245e2b374fa364659ed4d122e | D6: https://github.com/apple/swift/commit/41cdfb04adfe13839af9e9867f775559ee307296 | E6: Unify diagnose invalid attr producing | F6: Introduce a proper TypeAttribute class hierarchy. The old TypeAttributes reprsentation wasn't too bad for a small number of simple attributes. Unfortunately, the number of attributes has grown over the years by quite a bit, which makes TypeAttributes fairly bulky even at just a single SourceLoc per attribute. The bigger problem is that we want to carry more information than that on some of these attributes, which is all super ad hoc and awkward. And given that we want to do some things for each attribute we see, like diagnosing unapplied attributes, the linear data structure does require a fair amount of extra work. I switched around the checking logic quite a bit in order to try to fit in with the new representation better. The most significant change here is the change to how we handle implicit noescape, where now we're passing the escaping attribute's presence down in the context instead of resetting the context anytime we see any attributes at all. This should be cleaner overall. The source range changes around some of the @escaping checking is really a sort of bugfix --- the existing code was really jumping from the @ sign all the way past the autoclosure keyword in a way that I'm not sure always works and is definitely a little unintentional-feeling. I tried to make the parser logic more consistent around recognizing these parameter specifiers; it seems better now, at least. | H6: 0beddca9e93643a245e2b374fa364659ed4d122e | I6: lib/Sema/TypeCheckType.cpp | J6: (2421, 9) | K6: lib/Sema/TypeCheckType.cpp | L6: (2414, 5) | M6: 41cdfb04adfe13839af9e9867f775559ee307296 | N6: lib/Sema/TypeCheckType.cpp | O6: (3376, 38) | P6: lib/Sema/TypeCheckType.cpp | R6: auto diag = diagnoseInvalid(repr, attrs.getLoc(i), diag::escaping_optional_type_argument); | S6: const auto diagnoseInvalidAttr = [&](TypeAttrKind kind) { if (kind == TAK_escaping) { Type optionalObjectType = ty->getOptionalObjectType(); if (optionalObjectType && optionalObjectType->is<AnyFunctionType>()) { return diagnoseInvalid(repr, attrs.getLoc(kind), diag::escaping_optional_type_argument); } } return diagnoseInvalid(repr, attrs.getLoc(kind), diag::attribute_requires_function_type, TypeAttributes::getAttrName(kind)); }; | T6: [&](TypeAttrKind kind) { if (kind == TAK_escaping) { Type optionalObjectType = ty->getOptionalObjectType(); if (optionalObjectType && optionalObjectType->is<AnyFunctionType>()) { return diagnoseInvalid(repr, attrs.getLoc(kind), diag::escaping_optional_type_argument); } } return diagnoseInvalid(repr, attrs.getLoc(kind), diag::attribute_requires_function_type, TypeAttributes::getAttrName(kind)); }
A7: 5 | B7: apple_swift | C7: https://github.com/apple/swift/commit/10fc3fa54677a7023079f70f0600a209777edffe | D7: https://github.com/apple/swift/commit/3d5ca29993eb4b2f11f502cd0c812d1238a72557 | E7: [GenericSig Builder] Make resolve() less representative-dependent. `GenericSignatureBuilder::resolve()` was always jumping to the representative, to treat typealias representatives as special. However, doing this means that we put the same-type constraint on the wrong potential archetype (with the wrong source). Eliminate the use of `getRepresentative()`. This unfortunately causes us to need recursive resolution, because we can't always depend on jumping to the representative to avoid it. | F7: GSB: Dump conformance and same-type requirement sources in EquivalenceClass::dump() | H7: 10fc3fa54677a7023079f70f0600a209777edffe | I7: lib/AST/GenericSignatureBuilder.cpp | J7: (902, 3) | K7: lib/AST/GenericSignatureBuilder.cpp | L7: (900, 3) | M7: 3d5ca29993eb4b2f11f502cd0c812d1238a72557 | N7: lib/AST/GenericSignatureBuilder.cpp | O7: (2171, 7) | P7: lib/AST/GenericSignatureBuilder.cpp | R7: builder.addSameTypeRequirement(nestedPA, witnessType, source); | S7: builder.addSameTypeRequirement(nestedPA, witnessType, source, [&](Type type1, Type type2) { builder.getASTContext().Diags.diagnose( source->getLoc(), diag::requires_same_type_conflict, nestedPA->getDependentType(/*FIXME: */{ }, true), type1, type2); }); | T7: [&](const Constraint<Type> &constraint) { out << "\n " << constraint.getSubjectDependentType({}) << " == " << constraint.value; if (constraint.source->isDerivedRequirement()) out << " [derived]"; }
A8: 6 | B8: eosforce_eosforce | C8: https://github.com/eosforce/eosforce/commit/4a588b479f292c0b29ecc41f1679f914326f4174 | D8: https://github.com/eosforce/eosforce/commit/7a084347167d752c4a9509e79ebad809f398bf75 | E8: Avoid tying up a thread to wait on transaction future. Also removes likely safe but undefined behavior. | F8: Revert to 1.8.1 version of signature recovery | H8: 4a588b479f292c0b29ecc41f1679f914326f4174 | I8: plugins/producer_plugin/producer_plugin.cpp | J8: (351, 150) | K8: plugins/producer_plugin/producer_plugin.cpp | L8: (351, 150) | M8: 7a084347167d752c4a9509e79ebad809f398bf75 | N8: plugins/producer_plugin/producer_plugin.cpp | O8: (415, 16) | P8: plugins/producer_plugin/producer_plugin.cpp | R8: { chain::controller& chain = chain_plug->chain(); const auto max_trx_time_ms = _max_transaction_time_ms.load(); fc::microseconds max_trx_cpu_usage = max_trx_time_ms < 0 ? fc::microseconds::maximum() : fc::milliseconds( max_trx_time_ms ); auto& tp = *_thread_pool; // use chain thread pool for sig recovery so that future wait below is not in the same thread pool preventing progress transaction_metadata::create_signing_keys_future( trx, tp, chain.get_chain_id(), max_trx_cpu_usage ); boost::asio::post( tp, [self = this, trx, persist_until_expired, next]() { if( trx->signing_keys_future.valid() ) trx->signing_keys_future.wait(); app().post(priority::low, [self, trx, persist_until_expired, next]() { self->process_incoming_transaction_async( trx, persist_until_expired, next ); }); }); } | S8: { chain::controller& chain = chain_plug->chain(); const auto max_trx_time_ms = _max_transaction_time_ms.load(); fc::microseconds max_trx_cpu_usage = max_trx_time_ms < 0 ? fc::microseconds::maximum() : fc::milliseconds( max_trx_time_ms ); auto& tp = *_thread_pool; // use chain thread pool for sig recovery so that future wait below is not in the same thread pool preventing progress transaction_metadata::create_signing_keys_future( trx, chain.get_thread_pool(), chain.get_chain_id(), max_trx_cpu_usage, [self = this, trx, persist_until_expired, next{std::move(next)} | T8: [self = this, trx, persist_until_expired, next{std::move(next)
A9: 7 | B9: apple_swift | C9: https://github.com/apple/swift/commit/0a1f7c09dfc4af6b856b45058d20118039ef1b4d | D9: https://github.com/apple/swift/commit/5ead9764bd79b91ec973c4964488330f6aa69958 | E9: Revert "Fix unreachable code handling to properly diagnose things like:" This reverts commit 28678. It broke the IDE/complete_exception.swift test. Swift SVN r28679 | F9: Fix unreachable code handling to properly diagnose things like: throw x whatever() as being unreachable after the throw. Swift SVN r28678 | H9: 0a1f7c09dfc4af6b856b45058d20118039ef1b4d | I9: lib/Parse/ParseStmt.cpp | J9: (650, 3) | K9: lib/Parse/ParseStmt.cpp | L9: (90, 3) | M9: 5ead9764bd79b91ec973c4964488330f6aa69958 | N9: lib/Parse/ParseStmt.cpp | O9: (90, 28) | P9: lib/Parse/ParseStmt.cpp | R9: SourceLoc throwLoc = consumeToken(tok::kw_throw); | S9: auto parseTopLevelExpr = [&](Diag<> ID) { return (Tok.is(tok::kw_throw) ? parseExprThrow(ID) : parseExpr(ID)); }; | T9: [&](Diag<> ID) { return (Tok.is(tok::kw_throw) ? parseExprThrow(ID) : parseExpr(ID)); }
A10: 8 | B10: apple_swift | C10: https://github.com/apple/swift/commit/63dc900f91498a439738dee6de58e55629c01fd0 | D10: https://github.com/apple/swift/commit/bfbc6142c16b26c9839f8c5da3e329f1a06ea652 | E10: Pattern processing cleanups, NFC: Introduce a new Pattern::forEachVariable that takes a lambda and iterates over all the variables encompassed by the pattern (the ones found by collectVariables) and runs the lambda on it. Use this to implement collectVariables, so we only have one copy of the code. Convert several places to use this, removing a bunch of duplicated code for walking the pattern structure and extracting decls. Convert a few uses of collectVariables to forEachVariable, leading to more clear code without a temporary smallvector. Remove simplifyPatternTypes in CSApply.cpp, which is dead. Swift SVN r13545 | F10: rework CleanupIllFormedExpression some more. It now makes sure to find typevars hiding withing TypeLocs in expressions as well, and handles closures with a simpler model. Swift SVN r30026 | H10: 63dc900f91498a439738dee6de58e55629c01fd0 | I10: lib/Sema/TypeCheckConstraints.cpp | J10: (468, 9) | K10: lib/Sema/TypeCheckConstraints.cpp | L10: (467, 9) | M10: bfbc6142c16b26c9839f8c5da3e329f1a06ea652 | N10: lib/Sema/TypeCheckConstraints.cpp | O10: (838, 45) | P10: lib/Sema/TypeCheckConstraints.cpp | R10: closure->getParams()->collectVariables(Params); | S10: closure->getParams()->forEachVariable([&](VarDecl *VD) { if (VD->hasType()) { Type T = VD->getType(); if (cs) T = cs->simplifyType(T); if (T->hasTypeVariable()) { T = ErrorType::get(context); VD->setInvalid(); } VD->overwriteType(T); } else { VD->setType(ErrorType::get(context)); VD->setInvalid(); } }); | T10: [&](VarDecl *VD) { if (VD->hasType() && !VD->getType()->hasTypeVariable()) return; VD->overwriteType(ErrorType::get(context)); VD->setInvalid(); }
A11: 9 | B11: apple_swift | C11: https://github.com/apple/swift/commit/0a1f7c09dfc4af6b856b45058d20118039ef1b4d | D11: https://github.com/apple/swift/commit/e517ad91828ae7e552a4fb3dbb9ac28833d76091 | E11: Revert "Fix unreachable code handling to properly diagnose things like:" This reverts commit 28678. It broke the IDE/complete_exception.swift test. Swift SVN r28679 | F11: Fix unreachable code handling to properly diagnose things like: throw x whatever() as being unreachable after the throw. Swift SVN r28680 | H11: 0a1f7c09dfc4af6b856b45058d20118039ef1b4d | I11: lib/Parse/ParseStmt.cpp | J11: (650, 3) | K11: lib/Parse/ParseStmt.cpp | L11: (90, 3) | M11: e517ad91828ae7e552a4fb3dbb9ac28833d76091 | N11: lib/Parse/ParseStmt.cpp | O11: (90, 28) | P11: lib/Parse/ParseStmt.cpp | R11: SourceLoc throwLoc = consumeToken(tok::kw_throw); | S11: auto parseTopLevelExpr = [&](Diag<> ID) { return (Tok.is(tok::kw_throw) ? parseExprThrow(ID) : parseExpr(ID)); }; | T11: [&](Diag<> ID) { return (Tok.is(tok::kw_throw) ? parseExprThrow(ID) : parseExpr(ID)); }
A12: 10 | B12: eosforce_eosforce | C12: https://github.com/eosforce/eosforce/commit/cf6e9ca9685b1ec60c296af5fb87f141d1f27267 | D12: https://github.com/eosforce/eosforce/commit/7a084347167d752c4a9509e79ebad809f398bf75 | E12: Avoid tying up a thread to wait on transaction future. Also removes likely safe but undefined behavior. | F12: Revert to 1.8.1 version of signature recovery | H12: cf6e9ca9685b1ec60c296af5fb87f141d1f27267 | I12: plugins/producer_plugin/producer_plugin.cpp | J12: (358, 83) | K12: plugins/producer_plugin/producer_plugin.cpp | L12: (358, 91) | M12: 7a084347167d752c4a9509e79ebad809f398bf75 | N12: plugins/producer_plugin/producer_plugin.cpp | O12: (416, 45) | P12: plugins/producer_plugin/producer_plugin.cpp | R12: { if( trx->signing_keys_future.valid() ) trx->signing_keys_future.wait(); app().post(priority::low, [self, trx, persist_until_expired, next]() { self->process_incoming_transaction_async( trx, persist_until_expired, next ); }); } | S12: { app().post(priority::low, [self, trx{std::move(trx)}, persist_until_expired, next{std::move(next)}]() { self->process_incoming_transaction_async( trx, persist_until_expired, next ); }); } | T12: [self, trx{std::move(trx)}
A13: 11 | B13: apple_swift | C13: https://github.com/apple/swift/commit/54ccdc67e7df313a8cfa6cac461602f8b59cf06b | D13: https://github.com/apple/swift/commit/2ebb1234217498f4629ef5887b4cadcba3ed762a | E13: AssociatedTypeInference: Delay substitutions into abstract type witnesses until after they have been computed | F13: AssociatedTypeInference: Properly substitute into tentative type witnesses in inferAbstractTypeWitnesses() A regular type.subst() is not enough, because tentative type witnesses may contain type parameters, and we have to substitute them as well, recursively, e.g A := G<B>, B := G<C>, C := Never. Avoiding subst() here also eliminates a use case of the getSubstOptionsWithCurrentTypeWitnesses() hack. | H13: 54ccdc67e7df313a8cfa6cac461602f8b59cf06b | I13: lib/Sema/TypeCheckProtocolInference.cpp | J13: (854, 3) | K13: lib/Sema/TypeCheckProtocolInference.cpp | L13: (1168, 9) | M13: 2ebb1234217498f4629ef5887b4cadcba3ed762a | N13: lib/Sema/TypeCheckProtocolInference.cpp | O13: (1162, 11) | P13: lib/Sema/TypeCheckProtocolInference.cpp | R13: defaultType = defaultType.subst( QueryTypeSubstitutionMap{substitutions}, LookUpConformanceInModule(dc->getParentModule())); | S13: type = type.subst( [&](SubstitutableType *type) { if (type->isEqual(proto->getSelfInterfaceType())) return adoptee; return Type(); }, LookUpConformanceInModule(dc->getParentModule()), getSubstOptionsWithCurrentTypeWitnesses()); | T13: [&](SubstitutableType *type) { if (type->isEqual(proto->getSelfInterfaceType())) return adoptee; return Type(); }
A14: 12 | B14: eosforce_eosforce | C14: https://github.com/eosforce/eosforce/commit/0a95f98c3ca94dacce8bfa487b74d749fd6aaee1 | D14: https://github.com/eosforce/eosforce/commit/ae6142aca837cf39a8da19e5dde3f0711d3fa217 | E14: issue 3497 - add new config to limit the number of client connections accepted from any one host IP address | F14: merge eos | H14: 0a95f98c3ca94dacce8bfa487b74d749fd6aaee1 | I14: plugins/net_plugin/net_plugin.cpp | J14: (1976, 7) | K14: plugins/net_plugin/net_plugin.cpp | L14: (1978, 7) | M14: ae6142aca837cf39a8da19e5dde3f0711d3fa217 | N14: plugins/net_plugin/net_plugin.cpp | O14: (1989, 40) | P14: plugins/net_plugin/net_plugin.cpp | R14: acceptor->async_accept( *socket, [socket,this]( boost::system::error_code ec ) { if( !ec ) { uint32_t visitors = 0; for (auto &conn : connections) { if(conn->socket->is_open() && conn->peer_addr.empty()) { visitors++; } } if (num_clients != visitors) { ilog ("checking max client, visitors = ${v} num clients ${n}",("v",visitors)("n",num_clients)); num_clients = visitors; } if( max_client_count == 0 || num_clients < max_client_count ) { ++num_clients; connection_ptr c = std::make_shared<connection>( socket ); connections.insert( c ); start_session( c ); } else { elog( "Error max_client_count ${m} exceeded", ( "m", max_client_count) ); socket->close( ); } start_listen_loop(); } else { elog( "Error accepting connection: ${m}",( "m", ec.message() ) ); } }); | S14: acceptor->async_accept( *socket, [socket,this]( boost::system::error_code ec ) { if( !ec ) { uint32_t visitors = 0; uint32_t from_addr = 0; auto paddr = socket->remote_endpoint(ec).address().to_v4(); if (ec) { fc_elog(logger,"Error getting remote endpoint: ${m}",("m", ec.message())); return; } | T14: [socket,this]( boost::system::error_code ec ) { if( !ec ) { uint32_t visitors = 0; uint32_t from_addr = 0; auto paddr = socket->remote_endpoint(ec).address().to_v4()
... A165: 163 | B165: apple_swift | C165: https://github.com/apple/swift/commit/83f9ed43c38f65c96cd37dbde05252388276618f | D165: https://github.com/apple/swift/commit/aee4c83467b6cb0444daecf2d3bdb54e6baa83d3 | E165: [Driver] Don't assert when some files /don't/ get rebuilt but we still merge modules. ...or do anything else that depends on the compile commands that get skipped. Fix-up to rdar://problem/21129029 Swift SVN r29816 | F165: [Driver] Move markFinished to PerformJobsState, add logging. | H165: 83f9ed43c38f65c96cd37dbde05252388276618f | I165: lib/Driver/Compilation.cpp | J165: (194, 3) | K165: lib/Driver/Compilation.cpp | L165: (232, 3) | M165: aee4c83467b6cb0444daecf2d3bdb54e6baa83d3 | N165: lib/Driver/Compilation.cpp | O165: (395, 23) | P165: lib/Driver/Compilation.cpp | R165: unsigned InitialBlockingCount = State.BlockingCommands.size(); | S165: auto markFinished = [&] (const Job *Cmd) { State.FinishedCommands.insert(Cmd); auto BlockedIter = State.BlockingCommands.find(Cmd); if (BlockedIter != State.BlockingCommands.end()) { auto AllBlocked = std::move(BlockedIter->second); State.BlockingCommands.erase(BlockedIter); for (auto *Blocked : AllBlocked) scheduleCommandIfNecessaryAndPossible(Blocked); } }; | T165: [&] (const Job *Cmd) { State.FinishedCommands.insert(Cmd); auto BlockedIter = State.BlockingCommands.find(Cmd); if (BlockedIter != State.BlockingCommands.end()) { auto AllBlocked = std::move(BlockedIter->second); State.BlockingCommands.erase(BlockedIter); for (auto *Blocked : AllBlocked) State.scheduleCommandIfNecessaryAndPossible(Blocked); } }

Sheet csharp_shuffle
B1: name_with_owner | C1: insert url | D1: delete url | E1: replacement_msg | F1: delete_msg | G1: coding | H1: insert commit | I1: insert src file | J1: insert src start pos | K1: insert dst file | L1: insert dst start pos | M1: delete commit | N1: delete src file | O1: delete src start pos | P1: delete dst file | Q1: delete dst start pos | R1: insert src file content | S1: insert dst file content | T1: delete src file content
A2: 0 | B2: signumsoftware_framework | C2: https://github.com/signumsoftware/framework/commit/fe7d3ff8826e4f2dfae0a3085882f37f3d990d5c | D2: https://github.com/signumsoftware/framework/commit/eb1b533826ad0b786fe883bdabdda8823e246a1b | E2: elefantes (TFS CS 5989) | F2: Chequinazo entitygroups (TFS CS 6663) | G2: 機能変更 | H2: fe7d3ff8826e4f2dfae0a3085882f37f3d990d5c | I2: Signum.Engine.Extensions/Authorization/EntityGroupAuthLogic.cs | J2: (116, 21) | K2: Signum.Engine.Extensions/Authorization/EntityGroupAuthLogic.cs | L2: (118, 21) | M2: eb1b533826ad0b786fe883bdabdda8823e246a1b | N2: Signum.Engine.Extensions/Authorization/EntityGroupAuthLogic.cs | O2: (133, 54) | P2: Signum.Engine.Extensions/Authorization/EntityGroupAuthLogic.cs | R2: ident.AssertAllowed(TypeAllowedBasic.Create, false); | S2: Transaction.PreRealCommit += () => ident.AssertAllowed(TypeAllowedBasic.Create, false); | T2: () => ident.AssertAllowed(TypeAllowedBasic.Create, Database.UserInterface)
A3: 1 | B3: Ginger-Automation_Ginger | C3: https://github.com/Ginger-Automation/Ginger/commit/58eaea8958fe9336d1c1be586932b7785c4735dd | D3: https://github.com/Ginger-Automation/Ginger/commit/79a02f5bfbdc412bf3872a44306b5d3876b855b3 | E3: Changed async void to task | F3: making AccountReport Logger method async | G3: 機能変更 | H3: 58eaea8958fe9336d1c1be586932b7785c4735dd | I3: Ginger/GingerCoreNET/Run/RunListenerLib/CenteralizedExecutionLogger/AccountReportExecutionLogger.cs | J3: (98, 13) | K3: Ginger/GingerCoreNET/Run/RunListenerLib/CenteralizedExecutionLogger/AccountReportExecutionLogger.cs | L3: (101, 13) | M3: 79a02f5bfbdc412bf3872a44306b5d3876b855b3 | N3: Ginger/GingerCoreNET/Run/RunListenerLib/CenteralizedExecutionLogger/AccountReportExecutionLogger.cs | O3: (119, 22) | P3: Ginger/GingerCoreNET/Run/RunListenerLib/CenteralizedExecutionLogger/AccountReportExecutionLogger.cs | R3: BusinessFlowStartTask(businessFlow); | S3: Task.Run(() => BusinessFlowStartTask(businessFlow)); | T3: () => BusinessFlowStartTask(businessFlow)
A4: 2 | B4: AutoMapper_AutoMapper | C4: https://github.com/AutoMapper/AutoMapper/commit/d8ea3389e0104fad7787964e369a1973697a0445 | D4: https://github.com/AutoMapper/AutoMapper/commit/fb68f979b31f4875d636d18d0e6f6dbd6c74fc7b | E4: Array mapping simplified quite a bit | F4: Instead of using ToArray, which double maps. Find lenth and manualy set. | G4: 機能変更 | H4: d8ea3389e0104fad7787964e369a1973697a0445 | I4: src/AutoMapper/Mappers/ArrayMapper.cs | J4: (46, 13) | K4: src/AutoMapper/Mappers/ArrayMapper.cs | L4: (29, 13) | M4: fb68f979b31f4875d636d18d0e6f6dbd6c74fc7b | N4: src/AutoMapper/Mappers/ArrayMapper.cs | O4: (21, 34) | P4: src/AutoMapper/Mappers/ArrayMapper.cs | R4: return array as TDestination; | S4: return source.Cast<TSourceElement>() .Select(item => (TDestinationElement) itemContext.Map(item, null, typeof(TSourceElement), typeof(TDestinationElement))) .ToArray(); | T4: item => newItemFunc(item, itemContext)
A5: 3 | B5: Ginger-Automation_Ginger | C5: https://github.com/Ginger-Automation/Ginger/commit/58eaea8958fe9336d1c1be586932b7785c4735dd | D5: https://github.com/Ginger-Automation/Ginger/commit/79a02f5bfbdc412bf3872a44306b5d3876b855b3 | E5: Changed async void to task | F5: making AccountReport Logger method async | G5: 機能変更 | H5: 58eaea8958fe9336d1c1be586932b7785c4735dd | I5: Ginger/GingerCoreNET/Run/RunListenerLib/CenteralizedExecutionLogger/AccountReportExecutionLogger.cs | J5: (84, 13) | K5: Ginger/GingerCoreNET/Run/RunListenerLib/CenteralizedExecutionLogger/AccountReportExecutionLogger.cs | L5: (87, 13) | M5: 79a02f5bfbdc412bf3872a44306b5d3876b855b3 | N5: Ginger/GingerCoreNET/Run/RunListenerLib/CenteralizedExecutionLogger/AccountReportExecutionLogger.cs | O5: (105, 22) | P5: Ginger/GingerCoreNET/Run/RunListenerLib/CenteralizedExecutionLogger/AccountReportExecutionLogger.cs | R5: RunnerRunEndTask(gingerRunner); | S5: Task.Run(() => RunnerRunEndTask(gingerRunner)); | T5: () => RunnerRunEndTask(gingerRunner)
A6: 4 | B6: signumsoftware_framework | C6: https://github.com/signumsoftware/framework/commit/058f6bf4968cfb578ba5b41f6b1e9bc1b07f5341 | D6: https://github.com/signumsoftware/framework/commit/9880339ef979a380e89089dacaab00ec86c3c093 | E6: TryToken and QueryTokenDN builder with error message | F6: SubTokens(canAggregate) | G6: 機能変更 | H6: 058f6bf4968cfb578ba5b41f6b1e9bc1b07f5341 | I6: Signum.Web.Extensions/Chart/ChartClient.cs | J6: (225, 13) | K6: Signum.Web.Extensions/Chart/ChartClient.cs | L6: (203, 13) | M6: 9880339ef979a380e89089dacaab00ec86c3c093 | N6: Signum.Web.Extensions/Chart/ChartClient.cs | O6: (202, 82) | P6: Signum.Web.Extensions/Chart/ChartClient.cs | R6: return sb.ToHtml(); | S6: return helper.QueryTokenDNBuilder(chartToken, context, qd.QueryName, t => t.SubTokensChart(qd.Columns, chart.GroupResults && canAggregate)); | T6: t => t.SubTokensChart(qd.Columns, chart.GroupResults && canAggregate)
A7: 5 | B7: rsdn_CodeJam | C7: https://github.com/rsdn/CodeJam/commit/589249fd5376b80b5ce93518ddf4f015e1537303 | D7: https://github.com/rsdn/CodeJam/commit/82bf9506fe7e1b8c4587b048c9762888cc8210d3 | E7: Operator templates: comparison operators | F7: Cleanup | G7: 機能変更 | H7: 589249fd5376b80b5ce93518ddf4f015e1537303 | I7: Main/src/Arithmetic/Operators.cs | J7: (21, 3) | K7: Main/src/Arithmetic/Operators.cs | L7: (21, 3) | M7: 82bf9506fe7e1b8c4587b048c9762888cc8210d3 | N7: Main/src/Arithmetic/Operators.cs | O7: (22, 30) | P7: Main/src/Arithmetic/Operators.cs | R7: public static readonly Func<T, T, int> Compare = GetComparisonCallback<T>(); | S7: private static readonly Lazy<Func<T, T, int>> _compare = new Lazy<Func<T, T, int>>(() => Comparison<T>(), LazyMode); | T7: () => Comparison<T>()
A8: 6 | B8: RomSunZ_StockSharp | C8: https://github.com/RomSunZ/StockSharp/commit/49e74fe59b234e164dfb35ffae702aa359a17519 | D8: https://github.com/RomSunZ/StockSharp/commit/dadfd5b0efa28a36665a8904be4dfd172b767f53 | E8: FIX connector. Client side no longer use QuickFix. Version 4.2.73 | F8: FixServer. No longer use QuickFix. | G8: 誤検出 | H8: 49e74fe59b234e164dfb35ffae702aa359a17519 | I8: Connectors/Quik/Lua/LuaFixTransactionMessageAdapter.cs | J8: (108, 6) | K8: Connectors/Quik/Lua/LuaFixTransactionMessageAdapter.cs | L8: (172, 6) | M8: dadfd5b0efa28a36665a8904be4dfd172b767f53 | N8: Connectors/Quik/Lua/LuaFixTransactionMessageAdapter.cs | O8: (58, 85) | P8: Connectors/Quik/Lua/LuaFixTransactionMessageAdapter.cs | R8: var condition = new QuikOrderCondition { Type = (QuikOrderConditionTypes)fixMsg.Type.Obj, Result = fixMsg.IsSetResult() ? (QuikOrderConditionResults?)fixMsg.Result.Obj : null, StopPriceCondition = (QuikStopPriceConditions)fixMsg.StopPriceCondition.Obj, StopPrice = fixMsg.IsSetStopPx() ? fixMsg.StopPx.Obj : (decimal?)null, StopLimitPrice = fixMsg.IsSetStopLimitPrice() ? fixMsg.StopLimitPrice.Obj : (decimal?)null, IsMarketStopLimit = fixMsg.IsSetIsMarketStopLimit() ? fixMsg.IsMarketStopLimit.Obj : (bool?)null, ConditionOrderId = fixMsg.IsSetConditionOrderId() ? fixMsg.ConditionOrderId.Obj : (long?)null, ConditionOrderSide = (Sides)fixMsg.ConditionOrderSide.Obj, ConditionOrderPartiallyMatched = fixMsg.IsSetConditionOrderPartiallyMatched() ? fixMsg.ConditionOrderPartiallyMatched.Obj : (bool?)null, ConditionOrderUseMatchedBalance = fixMsg.IsSetConditionOrderUseMatchedBalance() ? fixMsg.ConditionOrderUseMatchedBalance.Obj : (bool?)null, LinkedOrderPrice = fixMsg.IsSetLinkedOrderPrice() ? fixMsg.LinkedOrderPrice.Obj : (decimal?)null, LinkedOrderCancel = fixMsg.LinkedOrderCancel.Obj, Offset = fixMsg.IsSetOffset() ? fixMsg.Offset.Obj.ToUnit() : null, Spread = fixMsg.IsSetStopSpread() ? fixMsg.StopSpread.Obj.ToUnit() : null, IsMarketTakeProfit = fixMsg.IsSetIsMarketTakeProfit() ? fixMsg.IsMarketTakeProfit.Obj : (bool?)null, }; | S8: var executions = reader.ReadExecutionMessage(Session, SessionHolder.UtcOffset, tag => { switch ((QuikFixTags)tag) { case QuikFixTags.Type: type = reader.ReadInt(); return true; case QuikFixTags.StopPriceCondition: stopPriceCondition = reader.ReadInt(); return true; case QuikFixTags.ConditionOrderSide: conditionOrderSide = reader.ReadInt(); return true; case QuikFixTags.LinkedOrderCancel: linkedOrderCancel = reader.ReadBool(); return true; case QuikFixTags.Result: result = reader.ReadInt(); return true; case QuikFixTags.OtherSecurityCode: otherSecurityCode = reader.ReadString(); return true; case QuikFixTags.StopPrice: stopPrice = reader.ReadDecimal(); return true; case QuikFixTags.StopLimitPrice: stopLimitPrice = reader.ReadDecimal(); return true; case QuikFixTags.IsMarketStopLimit: isMarketStopLimit = reader.ReadBool(); return true; case QuikFixTags.ActiveTimeFrom: activeTimeFrom = reader.ReadDateTime().ApplyTimeZone(SessionHolder.UtcOffset); return true; case QuikFixTags.ActiveTimeTo: activeTimeTo = reader.ReadDateTime().ApplyTimeZone(SessionHolder.UtcOffset); return true; case QuikFixTags.ConditionOrderId: conditionOrderId = reader.ReadLong(); return true; case QuikFixTags.ConditionOrderPartiallyMatched: conditionOrderPartiallyMatched = reader.ReadBool(); return true; case QuikFixTags.ConditionOrderUseMatchedBalance: conditionOrderUseMatchedBalance = reader.ReadBool(); return true; case QuikFixTags.LinkedOrderPrice: linkedOrderPrice = reader.ReadDecimal(); return true; case QuikFixTags.Offset: offset = reader.ReadString(); return true; case QuikFixTags.StopSpread: stopSpread = reader.ReadString(); return true; case QuikFixTags.IsMarketTakeProfit: isMarketTakeProfit = reader.ReadBool(); return true; default: return false; } }); | T8: tag => { switch ((QuikFixTags)tag) { case QuikFixTags.Type: type = reader.ReadInt(); return true; case QuikFixTags.StopPriceCondition: stopPriceCondition = reader.ReadInt(); return true; case QuikFixTags.ConditionOrderSide: conditionOrderSide = reader.ReadInt(); return true; case QuikFixTags.LinkedOrderCancel: linkedOrderCancel = reader.ReadBool(); return true; case QuikFixTags.Result: result = reader.ReadInt(); return true; case QuikFixTags.OtherSecurityCode: otherSecurityCode = reader.ReadString(); return true; case QuikFixTags.StopPrice: stopPrice = reader.ReadDecimal(); return true; case QuikFixTags.StopLimitPrice: stopLimitPrice = reader.ReadDecimal(); return true; case QuikFixTags.IsMarketStopLimit: isMarketStopLimit = reader.ReadBool(); return true; case QuikFixTags.ActiveTimeFrom: activeTimeFrom = reader.ReadDateTime().ApplyTimeZone(SessionHolder.UtcOffset); return true; case QuikFixTags.ActiveTimeTo: activeTimeTo = reader.ReadDateTime().ApplyTimeZone(SessionHolder.UtcOffset); return true; case QuikFixTags.ConditionOrderId: conditionOrderId = reader.ReadLong(); return true; case QuikFixTags.ConditionOrderPartiallyMatched: conditionOrderPartiallyMatched = reader.ReadBool(); return true; case QuikFixTags.ConditionOrderUseMatchedBalance: conditionOrderUseMatchedBalance = reader.ReadBool(); return true; case QuikFixTags.LinkedOrderPrice: linkedOrderPrice = reader.ReadDecimal(); return true; case QuikFixTags.Offset: offset = reader.ReadString(); return true; case QuikFixTags.StopSpread: stopSpread = reader.ReadString(); return true; case QuikFixTags.IsMarketTakeProfit: isMarketTakeProfit = reader.ReadBool(); return true; default: return false; } }
A9: 7 | B9: signumsoftware_framework | C9: https://github.com/signumsoftware/framework/commit/d5e0bd110c5688280b0ba8565b271f63014e1b4c | D9: https://github.com/signumsoftware/framework/commit/40118cf0ba313e0aaeefb8a7f4a8478a40cc81bc | E9: dqm.RegisterQuery | F9: remove FileRepositoryEntity and add FileTypeAlgorithm.GetPrefixPair lambda instead to maximize flexibility | G9: 誤検出 | H9: d5e0bd110c5688280b0ba8565b271f63014e1b4c | I9: Signum.Engine.Extensions/Files/FilePathLogic.cs | J9: (50, 17) | K9: Signum.Engine.Extensions/Files/FilePathLogic.cs | L9: (50, 17) | M9: 40118cf0ba313e0aaeefb8a7f4a8478a40cc81bc | N9: Signum.Engine.Extensions/Files/FilePathLogic.cs | O9: (96, 65) | P9: Signum.Engine.Extensions/Files/FilePathLogic.cs | R9: dqm[typeof(FileRepositoryDN)] = (from r in Database.Query<FileRepositoryDN>() select new { Entity = r, r.Id, r.Name, r.Active, r.PhysicalPrefix, r.WebPrefix }).ToDynamic(); | S9: dqm.RegisterQuery(typeof(FileRepositoryDN), () => from r in Database.Query<FileRepositoryDN>() select new { Entity = r, r.Id, r.Name, r.Active, r.PhysicalPrefix, r.WebPrefix }); | T9: () => from r in Database.Query<FileRepositoryEntity>() select new { Entity = r, r.Id, r.Name, r.Active, r.PhysicalPrefix, r.WebPrefix }
A10: 8 | B10: Ginger-Automation_Ginger | C10: https://github.com/Ginger-Automation/Ginger/commit/58eaea8958fe9336d1c1be586932b7785c4735dd | D10: https://github.com/Ginger-Automation/Ginger/commit/79a02f5bfbdc412bf3872a44306b5d3876b855b3 | E10: Changed async void to task | F10: making AccountReport Logger method async | G10: 機能変更 | H10: 58eaea8958fe9336d1c1be586932b7785c4735dd | I10: Ginger/GingerCoreNET/Run/RunListenerLib/CenteralizedExecutionLogger/AccountReportExecutionLogger.cs | J10: (187, 13) | K10: Ginger/GingerCoreNET/Run/RunListenerLib/CenteralizedExecutionLogger/AccountReportExecutionLogger.cs | L10: (190, 13) | M10: 79a02f5bfbdc412bf3872a44306b5d3876b855b3 | N10: Ginger/GingerCoreNET/Run/RunListenerLib/CenteralizedExecutionLogger/AccountReportExecutionLogger.cs | O10: (208, 22) | P10: Ginger/GingerCoreNET/Run/RunListenerLib/CenteralizedExecutionLogger/AccountReportExecutionLogger.cs | R10: ActionStartTask(action); | S10: Task.Run(() => ActionStartTask(action)); | T10: () => ActionStartTask(action)
A11: 9 | B11: Ginger-Automation_Ginger | C11: https://github.com/Ginger-Automation/Ginger/commit/58eaea8958fe9336d1c1be586932b7785c4735dd | D11: https://github.com/Ginger-Automation/Ginger/commit/79a02f5bfbdc412bf3872a44306b5d3876b855b3 | E11: Changed async void to task | F11: making AccountReport Logger method async | G11: 機能変更 | H11: 58eaea8958fe9336d1c1be586932b7785c4735dd | I11: Ginger/GingerCoreNET/Run/RunListenerLib/CenteralizedExecutionLogger/AccountReportExecutionLogger.cs | J11: (127, 13) | K11: Ginger/GingerCoreNET/Run/RunListenerLib/CenteralizedExecutionLogger/AccountReportExecutionLogger.cs | L11: (130, 13) | M11: 79a02f5bfbdc412bf3872a44306b5d3876b855b3 | N11: Ginger/GingerCoreNET/Run/RunListenerLib/CenteralizedExecutionLogger/AccountReportExecutionLogger.cs | O11: (148, 22) | P11: Ginger/GingerCoreNET/Run/RunListenerLib/CenteralizedExecutionLogger/AccountReportExecutionLogger.cs | R11: await ActivityStartTask(activity); | S11: Task.Run(() => ActivityStartTask(activity)); | T11: () => ActivityStartTask(activity)
A12: 10 | B12: GridProtectionAlliance_gsf | C12: https://github.com/GridProtectionAlliance/gsf/commit/3f893ab0c9f494a7c017d1d81ec89d95c9824243 | D12: https://github.com/GridProtectionAlliance/gsf/commit/8335962581b65df64d12ab02b663457a074daa2a | E12: PIAdapters: Updated PI adapters to operate in a mode such that high-volume updates will be handled through multiple connections. git-tfs-id: [https://tfs.codeplex.com/tfs/TFS07]$/gsf/Main;C90732 | F12: PIAdapters: Moved all PI-SDK code to the STA operations thread. git-tfs-id: [https://tfs.codeplex.com/tfs/TFS07]$/gsf/Main;C90790 | G12: 機能変更 | H12: 3f893ab0c9f494a7c017d1d81ec89d95c9824243 | I12: Source/Libraries/Adapters/PIAdapters/PIOutputAdapter.cs | J12: (538, 33) | K12: Source/Libraries/Adapters/PIAdapters/PIOutputAdapter.cs | L12: (449, 25) | M12: 8335962581b65df64d12ab02b663457a074daa2a | N12: Source/Libraries/Adapters/PIAdapters/PIOutputAdapter.cs | O12: (510, 44) | P12: Source/Libraries/Adapters/PIAdapters/PIOutputAdapter.cs | R12: point.Data.UpdateValue(measurement.AdjustedValue, new DateTime(measurement.Timestamp).ToLocalTime()); | S12: connection.Execute(server => point.Data.UpdateValue(value, timestamp)); | T12: server => point.Data.UpdateValues(values)
A13: 11 | B13: GridProtectionAlliance_gsf | C13: https://github.com/GridProtectionAlliance/gsf/commit/5ea0dd4cf2052b91f62de9571271c083299201ae | D13: https://github.com/GridProtectionAlliance/gsf/commit/01fa19f073082541954aa85bad297354d6a22912 | E13: GSF.Web: Modified AuthenticationHandler to properly handle authentication and redirect behavior. | F13: GSF.Web: Added logout endpoint for applications using AuthenticationHandler. | G13: 機能変更 | H13: 5ea0dd4cf2052b91f62de9571271c083299201ae | I13: Source/Libraries/GSF.Web/Security/AuthenticationHandler.cs | J13: (162, 13) | K13: Source/Libraries/GSF.Web/Security/AuthenticationHandler.cs | L13: (158, 13) | M13: 01fa19f073082541954aa85bad297354d6a22912 | N13: Source/Libraries/GSF.Web/Security/AuthenticationHandler.cs | O13: (181, 29) | P13: Source/Libraries/GSF.Web/Security/AuthenticationHandler.cs | R13: return base.ApplyResponseChallengeAsync(); | S13: return Task.Run(() => { SecurityPrincipal securityPrincipal = Request.User as SecurityPrincipal; // If the user fails to authenticate, adjust the HTTP response if (!IsAnonymousResource(Request.Path.Value) && securityPrincipal?.Identity.IsAuthenticated != true) { string authFailRedirect = Request.Query["AuthFailRedirect"] ?? "True"; // Determine whether the authentication failure should redirect to login page if (authFailRedirect.ParseBoolean()) Response.Redirect(Options.LoginPage); else Response.StatusCode = (int)HttpStatusCode.Unauthorized; Response.ReasonPhrase = SecurityPrincipal.GetFailureReasonPhrase(securityPrincipal, AuthorizationType); return true; } return false; }); | T13: () => { SecurityPrincipal securityPrincipal = Request.User as SecurityPrincipal; string urlPath = Request.Path.Value; // If request is for an anonymous resource or user is properly authenticated, allow // request to propagate through the Owin pipeline if (Options.IsAnonymousResource(urlPath) || securityPrincipal?.Identity.IsAuthenticated == true) return false; // Let pipeline continue // Abort pipeline with appropriate response if (Options.IsAuthFailureRedirectResource(urlPath) && !IsAjaxCall()) { byte[] pathBytes; string base64Path, encodedPath, referrer = null; if (Request.Headers.TryGetValue("Referer", out string[] values) && values.Length == 1) { pathBytes = Encoding.UTF8.GetBytes(values[0]); base64Path = Convert.ToBase64String(pathBytes); encodedPath = WebUtility.UrlEncode(base64Path); referrer = $"&referrer={encodedPath}"; } string urlQueryString = Request.QueryString.HasValue ? "?" + Request.QueryString.Value : ""; pathBytes = Encoding.UTF8.GetBytes(urlPath + urlQueryString); base64Path = Convert.ToBase64String(pathBytes); encodedPath = WebUtility.UrlEncode(base64Path); Response.Redirect($"{Options.LoginPage}?redir={encodedPath}{referrer}"); } else { Response.StatusCode = (int)HttpStatusCode.Unauthorized; } // Add current identity to unauthorized response header string currentIdentity = securityPrincipal?.Identity.Name ?? "anonymous"; object value; if (Request.Environment.TryGetValue("OriginalPrincipal", out value)) { IPrincipal originalPrincpal = value as IPrincipal; if ((object)originalPrincpal != null && (object)originalPrincpal.Identity != null) currentIdentity = AdjustedUserName(originalPrincpal.Identity.Name); } bool debuggable = Common.GetApplicationType() != ApplicationType.Web && AssemblyInfo.EntryAssembly.Debuggable; Response.Headers.Add("CurrentIdentity", new[] { currentIdentity }); Response.ReasonPhrase = SecurityPrincipal.GetFailureReasonPhrase(securityPrincipal, AuthorizationHeader?.Scheme, debuggable); string failureReason = SecurityPrincipal.GetFailureReasonPhrase(securityPrincipal, AuthorizationHeader?.Scheme, true); Log.Publish(MessageLevel.Info, "AuthenticationFailure", $"Failed to authenticate {currentIdentity} for {Request.Path}: {failureReason}"); return true; // Abort pipeline }
... A59: 57 | B59: gregsdennis_Manatee.Trello | C59: https://github.com/gregsdennis/Manatee.Trello/commit/75018ca467c63c59e64759c6e56a7d252196d37b | D59: https://github.com/gregsdennis/Manatee.Trello/commit/857eb00cebe8ba989499174bfc00fe3e5622b075 | E59: initial efforts | F59: added board background collection | G59: 機能削除 | H59: 75018ca467c63c59e64759c6e56a7d252196d37b | I59: Manatee.Trello.UnitTests/DevTest.cs | J59: (26, 6) | K59: Manatee.Trello.UnitTests/DevTest.cs | L59: (36, 5) | M59: 857eb00cebe8ba989499174bfc00fe3e5622b075 | N59: Manatee.Trello.UnitTests/DevTest.cs | O59: (35, 21) | P59: Manatee.Trello.UnitTests/DevTest.cs | R59: Console.WriteLine($"before: {Environment.GetEnvironmentVariable("TEST_VAR", EnvironmentVariableTarget.User)}"); | S59: card.Updated += (c, list) => OutputCollection("properties", list); | T59: (c, list) => OutputCollection("properties", list)
A60: 58 | B60: openrails_openrails | C60: https://github.com/openrails/openrails/commit/021a2a635626b7c7ba09ea1a2893266b222e1dd0 | D60: https://github.com/openrails/openrails/commit/537214d61aacc637254915299a4bc6dbacb49870 | E60: Preliminary C# scripting framework and scriptable train control system. git-svn-id: http://svn.uktrainsim.com/svn/openrails/trunk@1970 a9f3cfff-6c41-7446-b0ca-052bd761e6eb | F60: A fix in TCS signalling and crash git-svn-id: http://svn.uktrainsim.com/svn/openrails/trunk@1979 a9f3cfff-6c41-7446-b0ca-052bd761e6eb | H60: 021a2a635626b7c7ba09ea1a2893266b222e1dd0 | I60: Source/RunActivity/RollingStock/TrainControlSystem.cs | J60: (191, 25) | K60: Source/RunActivity/RollingStock/TrainControlSystem.cs | L60: (245, 25) | M60: 537214d61aacc637254915299a4bc6dbacb49870 | N60: Source/RunActivity/RollingStock/TrainControlSystem.cs | O60: (247, 58) | P60: Source/RunActivity/RollingStock/TrainControlSystem.cs | R60: nextSpeedLimitMpS = MSTSLocomotive.Train.IsFreight ? SignalSpeed.speed_freight : SignalSpeed.speed_pass; | S60: Script.NextSignalSpeedLimitMpS = () => Locomotive.Train.IsFreight ? SignalSpeed.speed_freight : SignalSpeed.speed_pass; | T60: () => Locomotive.Train.IsFreight ? SignalSpeed.speed_freight : SignalSpeed.speed_pass
A61: 59 | B61: RomSunZ_StockSharp | C61: https://github.com/RomSunZ/StockSharp/commit/f90e77cc6c5ee9b17ea0722d9b7806290e843a4e | D61: https://github.com/RomSunZ/StockSharp/commit/14968937de25184c06bf00e666c589062457a35f | E61: Hydra. Connector's tasks small refactoring. | F61: prev commit fixes. | H61: f90e77cc6c5ee9b17ea0722d9b7806290e843a4e | I61: Hydra/Plugins/Blackwood/BlackwoodTask.cs | J61: (140, 4) | K61: Hydra/Plugins/Blackwood/BlackwoodTask.cs | L61: (140, 4) | M61: 14968937de25184c06bf00e666c589062457a35f | N61: Hydra/Plugins/Blackwood/BlackwoodTask.cs | O61: (141, 85) | P61: Hydra/Plugins/Blackwood/BlackwoodTask.cs | R61: return new MarketDataConnector<BlackwoodTrader>(EntityRegistry.Securities, this, CreateConnector); | S61: return new MarketDataConnector<BlackwoodTrader>(EntityRegistry.Securities, this, () => new BlackwoodTrader { HistoricalDataAddress = _settings.HistoricalDataAddress, MarketDataAddress = _settings.MarketDataAddress, Login = _settings.Login, Password = _settings.Password.To<string>(), }); | T61: () => new BlackwoodTrader { HistoricalDataAddress = _settings.HistoricalDataAddress, MarketDataAddress = _settings.MarketDataAddress, Login = _settings.Login, Password = _settings.Password.To<string>(), }
A62: 60 | B62: Ginger-Automation_Ginger | C62: https://github.com/Ginger-Automation/Ginger/commit/a57b53c679f1e45638a6fec2dfff664fc71ed1b9 | D62: https://github.com/Ginger-Automation/Ginger/commit/9b801948ee394f20efa5725bcbdab165622e98f6 | E62: working feature. need some little checks to be looked in deapth. | F62: Enhancing SR Find usage page to be async | H62: a57b53c679f1e45638a6fec2dfff664fc71ed1b9 | I62: Ginger/Ginger/AutomatePageLib/AddActionMenu/SharedRepositoryLib/RepositoryItemUsagePage.xaml.cs | J62: (299, 33) | K62: Ginger/Ginger/AutomatePageLib/AddActionMenu/SharedRepositoryLib/RepositoryItemUsagePage.xaml.cs | L62: (298, 33) | M62: 9b801948ee394f20efa5725bcbdab165622e98f6 | N62: Ginger/Ginger/AutomatePageLib/AddActionMenu/SharedRepositoryLib/RepositoryItemUsagePage.xaml.cs | O62: (300, 56) | P62: Ginger/Ginger/AutomatePageLib/AddActionMenu/SharedRepositoryLib/RepositoryItemUsagePage.xaml.cs | R62: mRepoItem.UpdateInstance(usage.UsageItem, usage.SelectedItemPart, usage.HostActivity); | S62: this.Dispatcher.Invoke(() => mRepoItem.UpdateInstance(usage.UsageItem, usage.SelectedItemPart, usage.HostActivity)); | T62: () => mRepoItem.UpdateInstance(usage.UsageItem, usage.SelectedItemPart, usage.HostActivity)
A63: 61 | B63: mob-sakai_ParticleEffectForUGUI | C63: https://github.com/mob-sakai/ParticleEffectForUGUI/commit/0d4a5875d130c74a573f713b46e109b7affefb21 | D63: https://github.com/mob-sakai/ParticleEffectForUGUI/commit/b76bf5a5ad378c3c4b16bcf08d21337757557101 | E63: 3.0.0-preview.19 # [3.0.0-preview.19](https://github.com/mob-sakai/ParticleEffectForUGUI/compare/v3.0.0-preview.18...v3.0.0-preview.19) (2020-08-28) ### Bug Fixes * baking camera settings for camera space ([436c5e4](https://github.com/mob-sakai/ParticleEffectForUGUI/commit/436c5e47f75c3e167dcd77c188847e9d7d6ea68d)) * fix local simulation ([7add9de](https://github.com/mob-sakai/ParticleEffectForUGUI/commit/7add9defb70be29ddbe536d854591c2e0d9e83fa)) ### Features * add menu to create UIParticle ([2fa1843](https://github.com/mob-sakai/ParticleEffectForUGUI/commit/2fa18431f0c8c4aeadfdd1cb98eeeef5ac6970a0)) * add play/pause/stop api ([f09a386](https://github.com/mob-sakai/ParticleEffectForUGUI/commit/f09a386bc59fbab8143f7f0b814c8684aea7f27c)) * support for changing rendering orders ([745d4a5](https://github.com/mob-sakai/ParticleEffectForUGUI/commit/745d4a598846b3e77d1071433079fdd5140921a8)) * Support for child ParticleSystem rendering ([4ee90be](https://github.com/mob-sakai/ParticleEffectForUGUI/commit/4ee90be17c68bf405f81f432615a3eebaa022366)) * UIParticle for trail is no longer needed ([466e43c](https://github.com/mob-sakai/ParticleEffectForUGUI/commit/466e43cf931d211907419f804a90776a0d9f4906)) ### BREAKING CHANGES * The child UIParticle is no longer needed. | F63: feat: support 8+ materials Instead of one CanvasRenderer with submeshes, render with multiple CanvasRenderers. This feature allows the number of materials to be unlimited. close #122, close #152, close #186 | H63: 0d4a5875d130c74a573f713b46e109b7affefb21 | I63: Scripts/UIParticle.cs | J63: (241, 13) | K63: Scripts/UIParticle.cs | L63: (228, 13) | M63: b76bf5a5ad378c3c4b16bcf08d21337757557101 | N63: Scripts/UIParticle.cs | O63: (442, 32) | P63: Scripts/UIParticle.cs | R63: CheckMaterials(); | S63: particles.Exec(p => p.GetComponent<ParticleSystemRenderer>().enabled = true); | T63: p => p.GetComponent<ParticleSystemRenderer>().enabled = true
A64: 62 | B64: mikebridge_Liquid.NET | C64: https://github.com/mikebridge/Liquid.NET/commit/eb1884ea62bde7a263908440de2556dc0da63309 | D64: https://github.com/mikebridge/Liquid.NET/commit/3f10c3eb157c8daed8914fa8fc685e0d6aa1d389 | E64: more shopify filters | F64: minor cleanup in filters | H64: eb1884ea62bde7a263908440de2556dc0da63309 | I64: Liquid.NET/src/Filters/Strings/UpCaseFilter.cs | J64: (13, 13) | K64: Liquid.NET/src/Filters/Strings/UpCaseFilter.cs | L64: (10, 13) | M64: 3f10c3eb157c8daed8914fa8fc685e0d6aa1d389 | N64: Liquid.NET/src/Filters/Strings/UpCaseFilter.cs | O64: (11, 86) | P64: Liquid.NET/src/Filters/Strings/UpCaseFilter.cs | R64: return new StringValue(val.ToUpper()); | S64: return StringResult.Eval(objectExpression, x => x.ToLower()); | T64: x => x.ToUpper()
